Workbook
Name ExternalData_1: 'CLEAN DATA'!$A$1:$N$3920

Sheet CLEAN DATA
A1: director_name | B1: num_critic_for_reviews | C1: duration | D1: gross | E1: genres | F1: actor_1_name | G1: movie_title | H1: num_voted_users | I1: num_user_for_reviews | J1: language | K1: country | L1: budget | M1: title_year | N1: imdb_score | O1: Profit
A2: Frank Darabont | B2: 199 | C2: 142 | D2: 28341469 | E2: Crime|Drama | F2: Morgan Freeman | G2: The Shawshank Redemption | H2: 1689764 | I2: 4144 | J2: English | K2: USA | L2: 25000000 | M2: 1994 | N2: 9.3 | O2: ='CLEAN DATA'!$D2-'CLEAN DATA'!$L2 -> 3341469
A3: Francis Ford Coppola | B3: 208 | C3: 175 | D3: 134821952 | E3: Crime|Drama | F3: Al Pacino | G3: The Godfather | H3: 1155770 | I3: 2238 | J3: English | K3: USA | L3: 6000000 | M3: 1972 | N3: 9.2 | O3: ='CLEAN DATA'!$D3-'CLEAN DATA'!$L3 -> 128821952
A4: Christopher Nolan | B4: 645 | C4: 152 | D4: 533316061 | E4: Action|Crime|Drama|Thriller | F4: Christian Bale | G4: The Dark Knight | H4: 1676169 | I4: 4667 | J4: English | K4: USA | L4: 185000000 | M4: 2008 | N4: 9 | O4: ='CLEAN DATA'!$D4-'CLEAN DATA'!$L4 -> 348316061
A5: Francis Ford Coppola | B5: 149 | C5: 220 | D5: 57300000 | E5: Crime|Drama | F5: Robert De Niro | G5: The Godfather: Part II | H5: 790926 | I5: 650 | J5: English | K5: USA | L5: 13000000 | M5: 1974 | N5: 9 | O5: ='CLEAN DATA'!$D5-'CLEAN DATA'!$L5 -> 44300000
A6: Peter Jackson | B6: 328 | C6: 192 | D6: 377019252 | E6: Action|Adventure|Drama|Fantasy | F6: Orlando Bloom | G6: The Lord of the Rings: The Return of the King | H6: 1215718 | I6: 3189 | J6: English | K6: USA | L6: 94000000 | M6: 2003 | N6: 8.9 | O6: ='CLEAN DATA'!$D6-'CLEAN DATA'!$L6 -> 283019252
A7: Steven Spielberg | B7: 174 | C7: 185 | D7: 96067179 | E7: Biography|Drama|History | F7: Liam Neeson | G7: Schindler's List | H7: 865020 | I7: 1273 | J7: English | K7: USA | L7: 22000000 | M7: 1993 | N7: 8.9 | O7: ='CLEAN DATA'!$D7-'CLEAN DATA'!$L7 -> 74067179
A8: Quentin Tarantino | B8: 215 | C8: 178 | D8: 107930000 | E8: Crime|Drama | F8: Bruce Willis | G8: Pulp Fiction | H8: 1324680 | I8: 2195 | J8: English | K8: USA | L8: 8000000 | M8: 1994 | N8: 8.9 | O8: ='CLEAN DATA'!$D8-'CLEAN DATA'!$L8 -> 99930000
A9: Sergio Leone | B9: 181 | C9: 142 | D9: 6100000 | E9: Western | F9: Clint Eastwood | G9: The Good, the Bad and the Ugly | H9: 503509 | I9: 780 | J9: Italian | K9: Italy | L9: 1200000 | M9: 1966 | N9: 8.9 | O9: ='CLEAN DATA'!$D9-'CLEAN DATA'!$L9 -> 4900000
A10: Christopher Nolan | B10: 642 | C10: 148 | D10: 292568851 | E10: Action|Adventure|Sci-Fi|Thriller | F10: Leonardo DiCaprio | G10: Inception | H10: 1468200 | I10: 2803 | J10: English | K10: USA | L10: 160000000 | M10: 2010 | N10: 8.8 | O10: ='CLEAN DATA'!$D10-'CLEAN DATA'!$L10 -> 132568851
A11: Peter Jackson | B11: 297 | C11: 171 | D11: 313837577 | E11: Action|Adventure|Drama|Fantasy | F11: Christopher Lee | G11: The Lord of the Rings: The Fellowship of the Ring | H11: 1238746 | I11: 5060 | J11: English | K11: New Zealand | L11: 93000000 | M11: 2001 | N11: 8.8 | O11: ='CLEAN DATA'!$D11-'CLEAN DATA'!$L11 -> 220837577
A12: David Fincher | B12: 315 | C12: 151 | D12: 37023395 | E12: Drama | F12: Brad Pitt | G12: Fight Club | H12: 1347461 | I12: 2968 | J12: English | K12: USA | L12: 63000000 | M12: 1999 | N12: 8.8 | O12: ='CLEAN DATA'!$D12-'CLEAN DATA'!$L12 -> -25976605
A13: Robert Zemeckis | B13: 149 | C13: 142 | D13: 329691196 | E13: Comedy|Drama | F13: Tom Hanks | G13: Forrest Gump | H13: 1251222 | I13: 1398 | J13: English | K13: USA | L13: 55000000 | M13: 1994 | N13: 8.8 | O13: ='CLEAN DATA'!$D13-'CLEAN DATA'!$L13 -> 274691196
... A552: Kay Pollak | B552: 34 | C552: 133 | D552: 9910 | E552: Comedy|Drama|Music|Romance | F552: Michael Nyqvist | G552: As It Is in Heaven | H552: 13543 | I552: 94 | J552: Swedish | K552: Sweden | L552: 25000000 | M552: 2004 | N552: 7.6 | O552: ='CLEAN DATA'!$D552-'CLEAN DATA'!$L552 -> -24990090
A553: Pan Nalin | B553: 15 | C553: 102 | D553: 16892 | E553: Documentary | G553: Ayurveda: Art of Being | H553: 341 | I553: 12 | J553: English | K553: India | L553: 300000 | M553: 2001 | N553: 7.6 | O553: ='CLEAN DATA'!$D553-'CLEAN DATA'!$L553 -> -283108
A554: Kevin Jordan | B554: 21 | C554: 90 | D554: 277233 | E554: Comedy|Romance | F554: Derick Martini | G554: Smiling Fish & Goat on Fire | H554: 2631 | I554: 26 | J554: English | K554: USA | L554: 40000 | M554: 1999 | N554: 7.6 | O554: ='CLEAN DATA'!$D554-'CLEAN DATA'!$L554 -> 237233
A555: Joss Whedon | B555: 635 | C555: 141 | D555: 458991599 | E555: Action|Adventure|Sci-Fi | F555: Chris Hemsworth | G555: Avengers: Age of Ultron | H555: 462669 | I555: 1117 | J555: English | K555: USA | L555: 250000000 | M555: 2015 | N555: 7.5 | O555: ='CLEAN DATA'!$D555-'CLEAN DATA'!$L555 -> 208991599
A556: David Yates | B556: 375 | C556: 153 | D556: 301956980 | E556: Adventure|Family|Fantasy|Mystery | F556: Alan Rickman | G556: Harry Potter and the Half-Blood Prince | H556: 321795 | I556: 973 | J556: English | K556: UK | L556: 250000000 | M556: 2009 | N556: 7.5 | O556: ='CLEAN DATA'!$D556-'CLEAN DATA'!$L556 -> 51956980
A557: Peter Jackson | B557: 422 | C557: 164 | D557: 255108370 | E557: Adventure|Fantasy | F557: Aidan Turner | G557: The Hobbit: The Battle of the Five Armies | H557: 354228 | I557: 802 | J557: English | K557: New Zealand | L557: 250000000 | M557: 2014 | N557: 7.5 | O557: ='CLEAN DATA'!$D557-'CLEAN DATA'!$L557 -> 5108370
A558: Justin Lin | B558: 322 | C558: 122 | D558: 130468626 | E558: Action|Adventure|Sci-Fi|Thriller | F558: Sofia Boutella | G558: Star Trek Beyond | H558: 53607 | I558: 432 | J558: English | K558: USA | L558: 185000000 | M558: 2016 | N558: 7.5 | O558: ='CLEAN DATA'!$D558-'CLEAN DATA'!$L558 -> -54531374
A559: Martin Scorsese | B559: 682 | C559: 126 | D559: 73820094 | E559: Adventure|Drama|Family|Mystery | F559: Chloë Grace Moretz | G559: Hugo | H559: 245333 | I559: 678 | J559: English | K559: USA | L559: 170000000 | M559: 2011 | N559: 7.5 | O559: ='CLEAN DATA'!$D559-'CLEAN DATA'!$L559 -> -96179906
A560: David Yates | B560: 329 | C560: 138 | D560: 292000866 | E560: Adventure|Family|Fantasy|Mystery | F560: Robert Pattinson | G560: Harry Potter and the Order of the Phoenix | H560: 355137 | I560: 1108 | J560: English | K560: UK | L560: 150000000 | M560: 2007 | N560: 7.5 | O560: ='CLEAN DATA'!$D560-'CLEAN DATA'!$L560 -> 142000866
A561: Chris Columbus | B561: 258 | C561: 159 | D561: 317557891 | E561: Adventure|Family|Fantasy | F561: Daniel Radcliffe | G561: Harry Potter and the Sorcerer's Stone | H561: 444683 | I561: 1571 | J561: English | K561: UK | L561: 125000000 | M561: 2001 | N561: 7.5 | O561: ='CLEAN DATA'!$D561-'CLEAN DATA'!$L561 -> 192557891
A562: Bryan Singer | B562: 289 | C562: 134 | D562: 214948780 | E562: Action|Adventure|Fantasy|Sci-Fi|Thriller | F562: Hugh Jackman | G562: X-Men 2 | H562: 405973 | I562: 1055 | J562: English | K562: Canada | L562: 110000000 | M562: 2003 | N562: 7.5 | O562: ='CLEAN DATA'!$D562-'CLEAN DATA'!$L562 -> 104948780
A563: Guy Ritchie | B563: 382 | C563: 129 | D563: 186830669 | E563: Action|Adventure|Crime|Mystery|Thriller | F563: Robert Downey Jr. | G563: Sherlock Holmes: A Game of Shadows | H563: 338635 | I563: 412 | J563: English | K563: USA | L563: 125000000 | M563: 2011 | N563: 7.5 | O563: ='CLEAN DATA'!$D563-'CLEAN DATA'!$L563 -> 61830669
A564: Paul Verhoeven | B564: 196 | C564: 113 | D564: 119412921 | E564: Action|Sci-Fi | F564: Ronny Cox | G564: Total Recall | H564: 240241 | I564: 391 | J564: English | K564: USA | L564: 65000000 | M564: 1990 | N564: 7.5 | O564: ='CLEAN DATA'!$D564-'CLEAN DATA'!$L564 -> 54412921
A565: Martin Scorsese | B565: 267 | C565: 170 | D565: 102608827 | E565: Biography|Drama | F565: Leonardo DiCaprio | G565: The Aviator | H565: 264318 | I565: 799 | J565: English | K565: USA | L565: 110000000 | M565: 2004 | N565: 7.5 | O565: ='CLEAN DATA'!$D565-'CLEAN DATA'!$L565 -> -7391173
... A744: Mira Nair | B744: 137 | C744: 114 | D744: 13876974 | E744: Comedy|Drama|Romance | F744: Naseeruddin Shah | G744: Monsoon Wedding | H744: 19397 | I744: 214 | J744: Hindi | K744: India | L744: 7000000 | M744: 2001 | N744: 7.4 | O744: ='CLEAN DATA'!$D744-'CLEAN DATA'!$L744 -> 6876974
A745: Léa Pool | B745: 23 | C745: 97 | D745: 24784 | E745: Documentary | G745: Pink Ribbons, Inc. | H745: 591 | I745: 10 | J745: English | K745: Canada | L745: 1200000 | M745: 2011 | N745: 7.4 | O745: ='CLEAN DATA'!$D745-'CLEAN DATA'!$L745 -> -1175216
A746: Derek Cianfrance | B746: 377 | C746: 112 | D746: 9701559 | E746: Drama|Romance | F746: Ryan Gosling | G746: Blue Valentine | H746: 141425 | I746: 283 | J746: English | K746: USA | L746: 3500000 | M746: 2010 | N746: 7.4 | O746: ='CLEAN DATA'!$D746-'CLEAN DATA'!$L746 -> 6201559
A747: Duncan Tucker | B747: 169 | C747: 103 | D747: 9013113 | E747: Adventure|Comedy|Drama | F747: Kevin Zegers | G747: Transamerica | H747: 36321 | I747: 230 | J747: English | K747: USA | L747: 1000000 | M747: 2005 | N747: 7.4 | O747: ='CLEAN DATA'!$D747-'CLEAN DATA'!$L747 -> 8013113
A748: Morgan Neville | B748: 149 | C748: 91 | D748: 4946250 | E748: Documentary|Music | F748: Sheryl Crow | G748: 20 Feet from Stardom | H748: 9540 | I748: 80 | J748: English | K748: USA | L748: 1000000 | M748: 2013 | N748: 7.4 | O748: ='CLEAN DATA'!$D748-'CLEAN DATA'!$L748 -> 3946250
A749: Goran Dukic | B749: 117 | C749: 88 | D749: 104077 | E749: Comedy|Drama|Fantasy|Romance | F749: Leslie Bibb | G749: Wristcutters: A Love Story | H749: 46076 | I749: 88 | J749: English | K749: USA | L749: 1000000 | M749: 2006 | N749: 7.4 | O749: ='CLEAN DATA'!$D749-'CLEAN DATA'!$L749 -> -895923
A750: Siddiq Barmak | B750: 105 | C750: 83 | D750: 1127331 | E750: Drama | F750: Marina Golbahari | G750: Osama | H750: 7559 | I750: 77 | J750: Dari | K750: Afghanistan | L750: 46000 | M750: 2003 | N750: 7.4 | O750: ='CLEAN DATA'!$D750-'CLEAN DATA'!$L750 -> 1081331
A751: Julie Taymor | B751: 156 | C751: 133 | D751: 24343673 | E751: Drama|Fantasy|Musical|Romance | F751: Jim Sturgess | G751: Across the Universe | H751: 91863 | I751: 524 | J751: English | K751: USA | L751: 45000000 | M751: 2007 | N751: 7.4 | O751: ='CLEAN DATA'!$D751-'CLEAN DATA'!$L751 -> -20656327
A752: Doug Liman | B752: 77 | C752: 96 | D752: 4505922 | E752: Comedy|Drama | F752: Jon Favreau | G752: Swingers | H752: 63951 | I752: 252 | J752: English | K752: USA | L752: 200000 | M752: 1996 | N752: 7.4 | O752: ='CLEAN DATA'!$D752-'CLEAN DATA'!$L752 -> 4305922
A753: Michel Orion Scott | B753: 29 | C753: 93 | D753: 155984 | E753: Documentary | F753: Temple Grandin | G753: The Horse Boy | H753: 586 | I753: 9 | J753: English | K753: USA | L753: 160000 | M753: 2009 | N753: 7.4 | O753: ='CLEAN DATA'!$D753-'CLEAN DATA'!$L753 -> -4016
A754: Kiyoshi Kurosawa | B754: 78 | C754: 111 | D754: 94596 | E754: Crime|Horror|Mystery|Thriller | F754: Kôji Yakusho | G754: The Cure | H754: 6318 | I754: 50 | J754: Japanese | K754: Japan | L754: 1000000 | M754: 1997 | N754: 7.4 | O754: ='CLEAN DATA'!$D754-'CLEAN DATA'!$L754 -> -905404
A755: Gore Verbinski | B755: 313 | C755: 151 | D755: 423032628 | E755: Action|Adventure|Fantasy | F755: Johnny Depp | G755: Pirates of the Caribbean: Dead Man's Chest | H755: 522040 | I755: 1832 | J755: English | K755: USA | L755: 225000000 | M755: 2006 | N755: 7.3 | O755: ='CLEAN DATA'!$D755-'CLEAN DATA'!$L755 -> 198032628
A756: Sam Raimi | B756: 300 | C756: 135 | D756: 373377893 | E756: Action|Adventure|Fantasy|Romance | F756: J.K. Simmons | G756: Spider-Man 2 | H756: 411164 | I756: 1303 | J756: English | K756: USA | L756: 200000000 | M756: 2004 | N756: 7.3 | O756: ='CLEAN DATA'!$D756-'CLEAN DATA'!$L756 -> 173377893
...

Sheet MOVIE GENRE
A1: GENRE | B1: imdb_score | C1: MOVIES NAME | I1: GENRE | J1: Count of GENRE | K1: Average | L1: Median | M1: Mode | N1: Variance | O1: SD | P1: Max | Q1: Min
A2: Crime | B2: 9.3 | C2: The Shawshank Redemption | E2: =COUNTIF(D:D,A2) -> 0 | I2: Action | J2: 976 | K2: =AVERAGEIF(A:A,I2,B:B) -> 6.282582 | L2: {=MEDIAN(IF(A:A="Action",B:B))} -> 6.3 | M2: {=MODE(IF(A:A=I2,B:B))} -> 6.6 | N2: {=_xlfn.VAR.P(IF(A:A="Action",B:B))} -> 1.0820737 | O2: {=_xlfn.STDEV.S(IF(A:A="Action",B:B))} -> 1.040761 | P2: {=MAX(IF(A:A="Action",B:B))} -> 9 | Q2: {=MIN(IF(A:A="Action",B:B))} -> 2.1
A3: Crime | B3: 9.2 | C3: The Godfather | I3: Adventure | J3: 380 | K3: =AVERAGEIF(A:A,I3,B:B) -> 6.5457895 | L3: {=MEDIAN(IF(A:A="Adventure",B:B))} -> 6.7 | M3: 7.3 | N3: 1.3 | O3: 1.1 | P3: 8.6 | Q3: 2.3
A4: Action | B4: 9 | C4: The Dark Knight | I4: Animation | J4: 47 | K4: =AVERAGEIF(A:A,I4,B:B) -> 6.6978723 | L4: {=MEDIAN(IF(A:A="Animation",B:B))} -> 7 | M4: 7.1 | N4: 1 | O4: 1 | P4: 8 | Q4: 4.5
A5: Crime | B5: 9 | C5: The Godfather: Part II | I5: Biography | J5: 209 | K5: =AVERAGEIF(A:A,I5,B:B) -> 7.1454545 | L5: {=MEDIAN(IF(A:A="Biography",B:B))} -> 7.2 | M5: 7 | N5: 0.5 | O5: 0.7 | P5: 8.9 | Q5: 4.5
A6: Action | B6: 8.9 | C6: The Lord of the Rings: The Return of the King | I6: Comedy | J6: 1041 | K6: =AVERAGEIF(A:A,I6,B:B) -> 6.1565802 | L6: {=MEDIAN(IF(A:A="Comedy",B:B))} -> 6.3 | M6: 6.4 | N6: 1.1 | O6: 1 | P6: 8.8 | Q6: 1.9
A7: Biography | B7: 8.9 | C7: Schindler's List | I7: Crime | J7: 262 | K7: =AVERAGEIF(A:A,I7,B:B) -> 6.9244275 | L7: {=MEDIAN(IF(A:A="Crime",B:B))} -> 7 | M7: 7.4 | N7: 0.8 | O7: 0.9 | P7: 9.3 | Q7: 3.1
A8: Crime | B8: 8.9 | C8: Pulp Fiction | I8: Documentary | J8: 43 | K8: =AVERAGEIF(A:A,I8,B:B) -> 6.9511628 | L8: {=MEDIAN(IF(A:A="Documentary",B:B))} -> 7.3 | M8: 7.3 | N8: 4 | O8: 2 | P8: 8.5 | Q8: 1.6
A9: Western | B9: 8.9 | C9: The Good, the Bad and the Ugly | I9: Drama | J9: 704 | K9: =AVERAGEIF(A:A,I9,B:B) -> 6.8056818 | L9: {=MEDIAN(IF(A:A="Drama",B:B))} -> 6.9 | M9: 7.3 | N9: 0.8 | O9: 0.9 | P9: 8.8 | Q9: 2.1
A10: Action | B10: 8.8 | C10: Inception | I10: Family | J10: 3 | K10: =AVERAGEIF(A:A,I10,B:B) -> 6.5 | L10: {=MEDIAN(IF(A:A="Family",B:B))} -> 5.9 | M10: N/A | N10: 1.5 | O10: 1.2 | P10: 7.9 | Q10: 5.7
A11: Action | B11: 8.8 | C11: The Lord of the Rings: The Fellowship of the Ring | I11: Fantasy | J11: 37 | K11: =AVERAGEIF(A:A,I11,B:B) -> 6.2810811 | L11: {=MEDIAN(IF(A:A="Fantasy",B:B))} -> 6.5 | M11: 6.8 | N11: 0.8 | O11: 0.9 | P11: 7.9 | Q11: 4.3
A12: Drama | B12: 8.8 | C12: Fight Club | I12: Horror | J12: 173 | K12: =AVERAGEIF(A:A,I12,B:B) -> 5.8 | L12: {=MEDIAN(IF(A:A="Horror",B:B))} -> 5.8 | M12: 5.9 | N12: 1.1 | O12: 1.1 | P12: 8.5 | Q12: 2.2
A13: Comedy | B13: 8.8 | C13: Forrest Gump | I13: Musical | J13: 2 | K13: =AVERAGEIF(A:A,I13,B:B) -> 6.75 | L13: {=MEDIAN(IF(A:A="Musical",B:B))} -> 6.75 | M13: N/A | N13: N/A | O13: N/A | P13: 7.2 | Q13: 7.2
A14: Action | B14: 8.8 | C14: Star Wars: Episode V - The Empire Strikes Back | I14: Mystery | J14: 23 | K14: =AVERAGEIF(A:A,I14,B:B) -> 6.6521739 | L14: {=MEDIAN(IF(A:A="Mystery",B:B))} -> 6.7 | M14: 7.1 | N14: 1.2 | O14: 1.1 | P14: 8.5 | Q14: 3.3
A15: Action | B15: 8.7 | C15: The Lord of the Rings: The Two Towers | I15: Romance | J15: 2 | K15: =AVERAGEIF(A:A,I15,B:B) -> 6.65 | L15: {=MEDIAN(IF(A:A="Romance",B:B))} -> 6.65 | M15: N/A | N15: N/A | O15: N/A | P15: 7.1 | Q15: 7.1
A16: Action | B16: 8.7 | C16: The Matrix | I16: Sci-Fi | J16: 10 | K16: =AVERAGEIF(A:A,I16,B:B) -> 5.95 | L16: {=MEDIAN(IF(A:A="Sci-Fi",B:B))} -> 6.2 | M16: N/A | N16: 1.4 | O16: 1.2 | P16: 8.2 | Q16: 5
A17: Biography | B17: 8.7 | C17: Goodfellas | I17: Thriller | J17: 3 | K17: =AVERAGEIF(A:A,I17,B:B) -> 5.3 | L17: {=MEDIAN(IF(A:A="Thriller",B:B))} -> 4.8 | M17: N/A | N17: 0.6 | O17: 0.8 | P17: 4.5 | Q17: 3.4
A18: Action | B18: 8.7 | C18: Star Wars: Episode IV - A New Hope | I18: Western | J18: 4 | K18: =AVERAGEIF(A:A,I18,B:B) -> 6.45 | L18: {=MEDIAN(IF(A:A="Western",B:B))} -> 6.4 | M18: N/A | N18: 1.4 | O18: 2.5 | P18: 7.3 | Q18: 3.8
A19: Drama | B19: 8.7 | C19: One Flew Over the Cuckoo's Nest | I19: (blank)
A20: Crime | B20: 8.7 | C20: City of God | I20: Grand Total | J20: 3919
A21: Action | B21: 8.7 | C21: Seven Samurai
A22: Adventure | B22: 8.6 | C22: Interstellar
A23: Action | B23: 8.6 | C23: Saving Private Ryan | O23: AVERAGE | P23: =AVERAGE(J2:J18) -> 230.52941
A24: Crime | B24: 8.6 | C24: Se7en | O24: MEDIAN | P24: =MEDIAN(J2:J18) -> 43
A25: Crime | B25: 8.6 | C25: The Silence of the Lambs | O25: MODE | P25: =MODE(J2:J18) -> 3
A26: Adventure | B26: 8.6 | C26: Spirited Away | O26: MAX | P26: =MAX(J2:J18) -> 1041
A27: Crime | B27: 8.6 | C27: American History X | O27: Min | P27: =MIN(J2:J18) -> 2
A28: Crime | B28: 8.6 | C28: The Usual Suspects | O28: Var | P28: =VAR(J2:J18) -> 120073.76
A29: Comedy | B29: 8.6 | C29: Modern Times | O29: sd | P29: =_xlfn.STDEV.S(J2:J18) -> 346.51662
A30: Action | B30: 8.5 | C30: The Dark Knight Rises | O30: Range | P30: =P26-P27 -> 1039
A31: Action | B31: 8.5 | C31: Gladiator
A32: Action | B32: 8.5 | C32: Terminator 2: Judgment Day
A33: Drama | B33: 8.5 | C33: Django Unchained
A34: Crime | B34: 8.5 | C34: The Departed
A35: Adventure | B35: 8.5 | C35: The Lion King
A36: Crime | B36: 8.5 | C36: The Green Mile
A37: Drama | B37: 8.5 | C37: The Prestige
A38: Biography | B38: 8.5 | C38: The Pianist
A39: Drama | B39: 8.5 | C39: Apocalypse Now
A40: Action | B40: 8.5 | C40: Raiders of the Lost Ark
...

Sheet MOVIES DURATION
A1: duration | B1: imdb_score
A2: 142 | B2: 9.3
A3: 175 | B3: 9.2
A4: 152 | B4: 9
A5: 220 | B5: 9
A6: 192 | B6: 8.9
A7: 185 | B7: 8.9
A8: 178 | B8: 8.9 | D8: Average | E8: =AVERAGE(A:A) -> 109.778
A9: 142 | B9: 8.9 | D9: Median | E9: =MEDIAN(A:A) -> 106
A10: 148 | B10: 8.8 | D10: STD. | E10: =_xlfn.STDEV.S(A:A) -> 22.693099
A11: 171 | B11: 8.8
A12: 151 | B12: 8.8
A13: 142 | B13: 8.8
A14: 127 | B14: 8.8
A15: 172 | B15: 8.7
A16: 136 | B16: 8.7
A17: 146 | B17: 8.7
A18: 125 | B18: 8.7
A19: 133 | B19: 8.7
A20: 135 | B20: 8.7
A21: 202 | B21: 8.7
A22: 169 | B22: 8.6
... A3920: 115 | B3920: 1.6

Sheet LANGUAGE ANALYSIS
A1: movie_title | B1: language | C1: imdb_score | E1: language | F1: Count of Movies | G1: Average of imdb | H1: Median | I1: S.d
A2: The Shawshank Redemption | B2: English | C2: 9.3 | E2: Aboriginal | F2: 2 | G2: =AVERAGEIF(B:B,E3,C:C) -> 7.2 | H2: {=MEDIAN(IF(B:B=E2,C:C))} -> 6.95 | I2: {=_xlfn.STDEV.S(IF(B:B=E2,C:C))} -> 0.77781746
A3: The Godfather | B3: English | C3: 9.2 | E3: Arabic | F3: 1 | G3: =AVERAGEIF(B:B,E4,C:C) -> 7.1 | H3: {=MEDIAN(IF(B:B=E3,C:C))} -> 7.2 | I3: 0
A4: The Dark Knight | B4: English | C4: 9 | E4: Aramaic | F4: 1 | G4: =AVERAGEIF(B:B,E5,C:C) -> 4.3 | H4: {=MEDIAN(IF(B:B=E4,C:C))} -> 7.1 | I4: 0
A5: The Godfather: Part II | B5: English | C5: 9 | E5: Bosnian | F5: 1 | G5: =AVERAGEIF(B:B,E6,C:C) -> 7.2375 | H5: {=MEDIAN(IF(B:B=E5,C:C))} -> 4.3 | I5: 0
A6: The Lord of the Rings: The Return of the King | B6: English | C6: 8.9 | E6: Cantonese | F6: 8 | G6: =AVERAGEIF(B:B,E7,C:C) -> 7.4 | H6: {=MEDIAN(IF(B:B=E6,C:C))} -> 7.3 | I6: {=_xlfn.STDEV.S(IF(B:B=E6,C:C))} -> 0.44057592
A7: Schindler's List | B7: English | C7: 8.9 | E7: Czech | F7: 1 | G7: =AVERAGEIF(B:B,E8,C:C) -> 7.9 | H7: {=MEDIAN(IF(B:B=E7,C:C))} -> 7.4 | I7: 0
A8: Pulp Fiction | B8: English | C8: 8.9 | E8: Danish | F8: 3 | G8: =AVERAGEIF(B:B,E9,C:C) -> 7.5 | H8: {=MEDIAN(IF(B:B=E8,C:C))} -> 8.1 | I8: {=_xlfn.STDEV.S(IF(B:B=E8,C:C))} -> 0.52915026
A9: The Good, the Bad and the Ugly | B9: Italian | C9: 8.9 | E9: Dari | F9: 2 | G9: =AVERAGEIF(B:B,E10,C:C) -> 7.5666667 | H9: {=MEDIAN(IF(B:B=E9,C:C))} -> 7.5 | I9: {=_xlfn.STDEV.S(IF(B:B=E9,C:C))} -> 0.14142136
A10: Inception | B10: English | C10: 8.8 | E10: Dutch | F10: 3 | G10: =AVERAGEIF(B:B,E11,C:C) -> 7.5 | H10: {=MEDIAN(IF(B:B=E10,C:C))} -> 7.8 | I10: {=_xlfn.STDEV.S(IF(B:B=E10,C:C))} -> 0.40414519
A11: The Lord of the Rings: The Fellowship of the Ring | B11: English | C11: 8.8 | E11: Dzongkha | F11: 1 | G11: =AVERAGEIF(B:B,E12,C:C) -> 6.4096653 | H11: {=MEDIAN(IF(B:B=E11,C:C))} -> 7.5 | I11: 0
A12: Fight Club | B12: English | C12: 8.8 | E12: English | F12: 3735 | G12: =AVERAGEIF(B:B,E13,C:C) -> 6.7 | H12: {=MEDIAN(IF(B:B=E12,C:C))} -> 6.5 | I12: {=_xlfn.STDEV.S(IF(B:B=E12,C:C))} -> 1.0624452
A13: Forrest Gump | B13: English | C13: 8.8 | E13: Filipino | F13: 1 | G13: =AVERAGEIF(B:B,E14,C:C) -> 7.2864865 | H13: {=MEDIAN(IF(B:B=E13,C:C))} -> 6.7 | I13: 0
A14: Star Wars: Episode V - The Empire Strikes Back | B14: English | C14: 8.8 | E14: French | F14: 37 | G14: =AVERAGEIF(B:B,E15,C:C) -> 7.6923077 | H14: {=MEDIAN(IF(B:B=E14,C:C))} -> 7.2 | I14: {=_xlfn.STDEV.S(IF(B:B=E14,C:C))} -> 0.56132886
A15: The Lord of the Rings: The Two Towers | B15: English | C15: 8.7 | E15: German | F15: 13 | G15: =AVERAGEIF(B:B,E16,C:C) -> 7.5 | H15: {=MEDIAN(IF(B:B=E15,C:C))} -> 7.7 | I15: {=_xlfn.STDEV.S(IF(B:B=E15,C:C))} -> 0.64091281
A16: The Matrix | B16: English | C16: 8.7 | E16: Hebrew | F16: 3 | G16: =AVERAGEIF(B:B,E17,C:C) -> 6.76 | H16: {=MEDIAN(IF(B:B=E16,C:C))} -> 7.3 | I16: {=_xlfn.STDEV.S(IF(B:B=E16,C:C))} -> 0.43588989
A17: Goodfellas | B17: English | C17: 8.7 | E17: Hindi | F17: 10 | G17: =AVERAGEIF(B:B,E18,C:C) -> 7.1 | H17: {=MEDIAN(IF(B:B=E17,C:C))} -> 7.05 | I17: {=_xlfn.STDEV.S(IF(B:B=E17,C:C))} -> 1.1117554
A18: Star Wars: Episode IV - A New Hope | B18: English | C18: 8.7 | E18: Hungarian | F18: 1 | G18: =AVERAGEIF(B:B,E19,C:C) -> 6.9 | H18: {=MEDIAN(IF(B:B=E18,C:C))} -> 7.1 | I18: 0
A19: One Flew Over the Cuckoo's Nest | B19: English | C19: 8.7 | E19: Icelandic | F19: 1 | G19: =AVERAGEIF(B:B,E20,C:C) -> 7.9 | H19: {=MEDIAN(IF(B:B=E19,C:C))} -> 6.9 | I19: 0
A20: City of God | B20: Portuguese | C20: 8.7 | E20: Indonesian | F20: 2 | G20: =AVERAGEIF(B:B,E21,C:C) -> 7.1857143 | H20: {=MEDIAN(IF(B:B=E20,C:C))} -> 7.9 | I20: {=_xlfn.STDEV.S(IF(B:B=E20,C:C))} -> 0.42426407
A21: Seven Samurai | B21: Japanese | C21: 8.7 | E21: Italian | F21: 7 | G21: =AVERAGEIF(B:B,E22,C:C) -> 7.625 | H21: {=MEDIAN(IF(B:B=E21,C:C))} -> 7 | I21: {=_xlfn.STDEV.S(IF(B:B=E21,C:C))} -> 1.155319
A22: Interstellar | B22: English | C22: 8.6 | E22: Japanese | F22: 12 | G22: =AVERAGEIF(B:B,E23,C:C) -> 6 | H22: {=MEDIAN(IF(B:B=E22,C:C))} -> 7.8 | I22: {=_xlfn.STDEV.S(IF(B:B=E22,C:C))} -> 0.89962113
A23: Saving Private Ryan | B23: English | C23: 8.6 | E23: Kazakh | F23: 1 | G23: =AVERAGEIF(B:B,E24,C:C) -> 7.7 | H23: {=MEDIAN(IF(B:B=E23,C:C))} -> 6 | I23: 0
A24: Se7en | B24: English | C24: 8.6 | E24: Korean | F24: 5 | G24: =AVERAGEIF(B:B,E25,C:C) -> 7.08 | H24: {=MEDIAN(IF(B:B=E24,C:C))} -> 7.7 | I24: {=_xlfn.STDEV.S(IF(B:B=E24,C:C))} -> 0.57008771
A25: The Silence of the Lambs | B25: English | C25: 8.6 | E25: Mandarin | F25: 15 | G25: =AVERAGEIF(B:B,E26,C:C) -> 7.8 | H25: {=MEDIAN(IF(B:B=E25,C:C))} -> 7.4 | I25: {=_xlfn.STDEV.S(IF(B:B=E25,C:C))} -> 0.77201036
A26: Spirited Away | B26: Japanese | C26: 8.6 | E26: Maya | F26: 1 | G26: =AVERAGEIF(B:B,E27,C:C) -> 7.3 | H26: {=MEDIAN(IF(B:B=E26,C:C))} -> 7.8 | I26: 0
A27: American History X | B27: English | C27: 8.6 | E27: Mongolian | F27: 1 | G27: =AVERAGEIF(B:B,E28,C:C) -> 8.5 | H27: {=MEDIAN(IF(B:B=E27,C:C))} -> 7.3 | I27: 0
A28: The Usual Suspects | B28: English | C28: 8.6 | E28: None | F28: 1 | G28: =AVERAGEIF(B:B,E29,C:C) -> 7.15 | H28: {=MEDIAN(IF(B:B=E28,C:C))} -> 8.5 | I28: 0
A29: Modern Times | B29: English | C29: 8.6 | E29: Norwegian | F29: 4 | G29: =AVERAGEIF(B:B,E30,C:C) -> 8.1333333 | H29: {=MEDIAN(IF(B:B=E29,C:C))} -> 7.3 | I29: {=_xlfn.STDEV.S(IF(B:B=E29,C:C))} -> 0.57445626
A30: The Dark Knight Rises | B30: English | C30: 8.5 | E30: Persian | F30: 3 | G30: =AVERAGEIF(B:B,E31,C:C) -> 7.76 | H30: {=MEDIAN(IF(B:B=E30,C:C))} -> 8.4 | I30: {=_xlfn.STDEV.S(IF(B:B=E30,C:C))} -> 0.55075705
A31: Gladiator | B31: English | C31: 8.5 | E31: Portuguese | F31: 5 | G31: =AVERAGEIF(B:B,E32,C:C) -> 7.9 | H31: {=MEDIAN(IF(B:B=E31,C:C))} -> 8 | I31: {=_xlfn.STDEV.S(IF(B:B=E31,C:C))} -> 0.97877474
A32: Terminator 2: Judgment Day | B32: English | C32: 8.5 | E32: Romanian | F32: 1 | G32: =AVERAGEIF(B:B,E33,C:C) -> 6.5 | H32: {=MEDIAN(IF(B:B=E32,C:C))} -> 7.9 | I32: 0
A33: Django Unchained | B33: English | C33: 8.5 | E33: Russian | F33: 1 | G33: =AVERAGEIF(B:B,E34,C:C) -> 7.05 | H33: {=MEDIAN(IF(B:B=E33,C:C))} -> 6.5 | I33: 0
A34: The Departed | B34: English | C34: 8.5 | E34: Spanish | F34: 26 | G34: =AVERAGEIF(B:B,E35,C:C) -> 7.6 | H34: {=MEDIAN(IF(B:B=E34,C:C))} -> 7.15 | I34: {=_xlfn.STDEV.S(IF(B:B=E34,C:C))} -> 0.8261961
A35: The Lion King | B35: English | C35: 8.5 | E35: Swedish | F35: 1 | G35: =AVERAGEIF(B:B,E36,C:C) -> 8.4 | H35: {=MEDIAN(IF(B:B=E35,C:C))} -> 7.6 | I35: 0
A36: The Green Mile | B36: English | C36: 8.5 | E36: Telugu | F36: 1 | G36: =AVERAGEIF(B:B,E37,C:C) -> 6.6333333 | H36: {=MEDIAN(IF(B:B=E36,C:C))} -> 8.4 | I36: 0
A37: The Prestige | B37: English | C37: 8.5 | E37: Thai | F37: 3 | G37: =AVERAGEIF(B:B,E38,C:C) -> 7.4 | H37: {=MEDIAN(IF(B:B=E37,C:C))} -> 6.6 | I37: {=_xlfn.STDEV.S(IF(B:B=E37,C:C))} -> 0.45092498
A38: The Pianist | B38: English | C38: 8.5 | E38: Vietnamese | F38: 1 | G38: =AVERAGEIF(B:B,E39,C:C) -> 7.3 | H38: {=MEDIAN(IF(B:B=E38,C:C))} -> 7.4 | I38: 0
A39: Apocalypse Now | B39: English | C39: 8.5 | E39: Zulu | F39: 1 | G39: 7.1 | H39: {=MEDIAN(IF(B:B=E39,C:C))} -> 7.3 | I39: 1
A40: Raiders of the Lost Ark | B40: English | C40: 8.5 | E40: (blank)
...

Sheet TOP 10 DIRECTORS
A1: movie_title | B1: director_name | C1: imdb_score
A2: The Shawshank Redemption | B2: Frank Darabont | C2: 9.3 | G2: HIGHEST | H2: =LARGE(G10:G19,1) -> 8.6
A3: The Godfather | B3: Francis Ford Coppola | C3: 9.2 | F3: CONCLUSION | G3: PERCENTILE RANK | H3: =PERCENTRANK(G10:G19,8.6) -> 0.888
A4: The Dark Knight | B4: Christopher Nolan | C4: 9 | G4: PERCENTILE | H4: =PERCENTILE(G10:G19,H3) -> 8.5992
A5: The Godfather: Part II | B5: Francis Ford Coppola | C5: 9
A6: The Lord of the Rings: The Return of the King | B6: Peter Jackson | C6: 8.9
A7: Schindler's List | B7: Steven Spielberg | C7: 8.9
A8: Pulp Fiction | B8: Quentin Tarantino | C8: 8.9
A9: The Good, the Bad and the Ugly | B9: Sergio Leone | C9: 8.9 | F9: Top 10 Directors | G9: Average of imdb_score
A10: Inception | B10: Christopher Nolan | C10: 8.8 | F10: Charles Chaplin | G10: 8.6
A11: The Lord of the Rings: The Fellowship of the Ring | B11: Peter Jackson | C11: 8.8 | F11: Tony Kaye | G11: 8.6
A12: Fight Club | B12: David Fincher | C12: 8.8 | F12: Alfred Hitchcock | G12: 8.5
A13: Forrest Gump | B13: Robert Zemeckis | C13: 8.8 | F13: Damien Chazelle | G13: 8.5
A14: Star Wars: Episode V - The Empire Strikes Back | B14: Irvin Kershner | C14: 8.8 | F14: Majid Majidi | G14: 8.5
A15: The Lord of the Rings: The Two Towers | B15: Peter Jackson | C15: 8.7 | F15: Ron Fricke | G15: 8.5
A16: The Matrix | B16: Lana Wachowski | C16: 8.7 | F16: Sergio Leone | G16: 8.4333333
A17: Goodfellas | B17: Martin Scorsese | C17: 8.7 | F17: Christopher Nolan | G17: 8.425
A18: Star Wars: Episode IV - A New Hope | B18: George Lucas | C18: 8.7 | F18: Asghar Farhadi | G18: 8.4
A19: One Flew Over the Cuckoo's Nest | B19: Milos Forman | C19: 8.7 | F19: Marius A. Markevicius | G19: 8.4
A20: City of God | B20: Fernando Meirelles | C20: 8.7
A21: Seven Samurai | B21: Akira Kurosawa | C21: 8.7
A22: Interstellar | B22: Christopher Nolan | C22: 8.6
A23: Saving Private Ryan | B23: Steven Spielberg | C23: 8.6
A24: Se7en | B24: David Fincher | C24: 8.6
A25: The Silence of the Lambs | B25: Jonathan Demme | C25: 8.6
A26: Spirited Away | B26: Hayao Miyazaki | C26: 8.6
A27: American History X | B27: Tony Kaye | C27: 8.6
A28: The Usual Suspects | B28: Bryan Singer | C28: 8.6
A29: Modern Times | B29: Charles Chaplin | C29: 8.6
A30: The Dark Knight Rises | B30: Christopher Nolan | C30: 8.5
A31: Gladiator | B31: Ridley Scott | C31: 8.5
... A3920: Justin Bieber: Never Say Never | B3920: Jon M. Chu | C3920: 1.6

Sheet MOVIE BUDGET
A1: gross | B1: budget | C1: Profit
A2: 28341469 | B2: 25000000 | C2: ='CLEAN DATA'!$D2-'CLEAN DATA'!$L2 -> 3341469
A3: 134821952 | B3: 6000000 | C3: ='CLEAN DATA'!$D3-'CLEAN DATA'!$L3 -> 128821952
A4: 533316061 | B4: 185000000 | C4: ='CLEAN DATA'!$D4-'CLEAN DATA'!$L4 -> 348316061
A5: 57300000 | B5: 13000000 | C5: ='CLEAN DATA'!$D5-'CLEAN DATA'!$L5 -> 44300000
A6: 377019252 | B6: 94000000 | C6: ='CLEAN DATA'!$D6-'CLEAN DATA'!$L6 -> 283019252 | E6: CORRELATION
A7: 96067179 | B7: 22000000 | C7: ='CLEAN DATA'!$D7-'CLEAN DATA'!$L7 -> 74067179 | E7: =CORREL(A:A,B:B) -> 0.10217736
A8: 107930000 | B8: 8000000 | C8: ='CLEAN DATA'!$D8-'CLEAN DATA'!$L8 -> 99930000
A9: 6100000 | B9: 1200000 | C9: ='CLEAN DATA'!$D9-'CLEAN DATA'!$L9 -> 4900000
A10: 292568851 | B10: 160000000 | C10: ='CLEAN DATA'!$D10-'CLEAN DATA'!$L10 -> 132568851 | E10: Hight profit margin movie | F10: HIGHT PROFIT MARGIN
A11: 313837577 | B11: 93000000 | C11: ='CLEAN DATA'!$D11-'CLEAN DATA'!$L11 -> 220837577 | E11: The Hobbit: The Desolation of Smaug | F11: =MAX(C:C) -> 523505847
A12: 37023395 | B12: 63000000 | C12: ='CLEAN DATA'!$D12-'CLEAN DATA'!$L12 -> -25976605
A13: 329691196 | B13: 55000000 | C13: ='CLEAN DATA'!$D13-'CLEAN DATA'!$L13 -> 274691196
A14: 290158751 | B14: 18000000 | C14: ='CLEAN DATA'!$D14-'CLEAN DATA'!$L14 -> 272158751
A15: 340478898 | B15: 94000000 | C15: ='CLEAN DATA'!$D15-'CLEAN DATA'!$L15 -> 246478898
A16: 171383253 | B16: 63000000 | C16: ='CLEAN DATA'!$D16-'CLEAN DATA'!$L16 -> 108383253
A17: 46836394 | B17: 25000000 | C17: ='CLEAN DATA'!$D17-'CLEAN DATA'!$L17 -> 21836394
A18: 460935665 | B18: 11000000 | C18: ='CLEAN DATA'!$D18-'CLEAN DATA'!$L18 -> 449935665
A19: 112000000 | B19: 4400000 | C19: ='CLEAN DATA'!$D19-'CLEAN DATA'!$L19 -> 107600000
A20: 7563397 | B20: 3300000 | C20: ='CLEAN DATA'!$D20-'CLEAN DATA'!$L20 -> 4263397
A21: 269061 | B21: 2000000 | C21: ='CLEAN DATA'!$D21-'CLEAN DATA'!$L21 -> -1730939
A22: 187991439 | B22: 165000000 | C22: ='CLEAN DATA'!$D22-'CLEAN DATA'!$L22 -> 22991439
A23: 216119491 | B23: 70000000 | C23: ='CLEAN DATA'!$D23-'CLEAN DATA'!$L23 -> 146119491
... A3293: 8025872 | B3293: 4700000 | C3293: ='CLEAN DATA'!$D3293-'CLEAN DATA'!$L3293 -> 3325872
B3294: 2100000 | C3294: ='CLEAN DATA'!$D3294-'CLEAN DATA'!$L3294 -> -2100000
B3295: 2000000 | C3295: ='CLEAN DATA'!$D3295-'CLEAN DATA'!$L3295 -> -2000000
B3296: 1800000 | C3296: ='CLEAN DATA'!$D3296-'CLEAN DATA'!$L3296 -> -1800000
B3297: 1500000 | C3297: ='CLEAN DATA'!$D3297-'CLEAN DATA'!$L3297 -> -1500000
B3298: 1455000 | C3298: ='CLEAN DATA'!$D3298-'CLEAN DATA'!$L3298 -> -1455000
B3299: 3150000 | C3299: ='CLEAN DATA'!$D3299-'CLEAN DATA'!$L3299 -> -3150000
B3300: 1250000 | C3300: ='CLEAN DATA'!$D3300-'CLEAN DATA'!$L3300 -> -1250000
A3301: 79363785 | B3301: 80000000 | C3301: ='CLEAN DATA'!$D3301-'CLEAN DATA'!$L3301 -> -636215
A3302: 62480 | B3302: 1000000 | C3302: ='CLEAN DATA'!$D3302-'CLEAN DATA'!$L3302 -> -937520
A3303: 77501 | B3303: 750000 | C3303: ='CLEAN DATA'!$D3303-'CLEAN DATA'!$L3303 -> -672499
A3304: 40542 | B3304: 300000 | C3304: ='CLEAN DATA'!$D3304-'CLEAN DATA'!$L3304 -> -259458
A3305: 191309 | B3305: 150000 | C3305: ='CLEAN DATA'!$D3305-'CLEAN DATA'!$L3305 -> 41309
A3306: 15180000 | B3306: 500000 | C3306: ='CLEAN DATA'!$D3306-'CLEAN DATA'!$L3306 -> 14680000
A3307: 47375327 | B3307: 176000000 | C3307: ='CLEAN DATA'!$D3307-'CLEAN DATA'!$L3307 -> -128624673
A3308: 100289690 | B3308: 175000000 | C3308: ='CLEAN DATA'!$D3308-'CLEAN DATA'!$L3308 -> -74710310
A3309: 21379315 | B3309: 150000000 | C3309: ='CLEAN DATA'!$D3309-'CLEAN DATA'!$L3309 -> -128620685
...
